[2023-08-28T20:47:14.005+0000] {taskinstance.py:1159} INFO - Dependencies all met for dep_context=non-requeueable deps ti=<TaskInstance: coin_data_dag.fetch_insert_task_2017_01_13 manual__2023-08-28T20:47:09.619213+00:00 [queued]>
[2023-08-28T20:47:14.015+0000] {taskinstance.py:1159} INFO - Dependencies all met for dep_context=requeueable deps ti=<TaskInstance: coin_data_dag.fetch_insert_task_2017_01_13 manual__2023-08-28T20:47:09.619213+00:00 [queued]>
[2023-08-28T20:47:14.016+0000] {taskinstance.py:1361} INFO - Starting attempt 1 of 2
[2023-08-28T20:47:14.032+0000] {taskinstance.py:1382} INFO - Executing <Task(PythonOperator): fetch_insert_task_2017_01_13> on 2023-08-28 20:47:09.619213+00:00
[2023-08-28T20:47:14.040+0000] {standard_task_runner.py:57} INFO - Started process 2015 to run task
[2023-08-28T20:47:14.059+0000] {standard_task_runner.py:84} INFO - Running: ['***', 'tasks', 'run', 'coin_data_dag', 'fetch_insert_task_2017_01_13', 'manual__2023-08-28T20:47:09.619213+00:00', '--job-id', '50', '--raw', '--subdir', 'DAGS_FOLDER/coin_data_dag.py', '--cfg-path', '/tmp/tmp2il4q8ot']
[2023-08-28T20:47:14.074+0000] {standard_task_runner.py:85} INFO - Job 50: Subtask fetch_insert_task_2017_01_13
[2023-08-28T20:47:14.168+0000] {task_command.py:415} INFO - Running <TaskInstance: coin_data_dag.fetch_insert_task_2017_01_13 manual__2023-08-28T20:47:09.619213+00:00 [running]> on host e5729120e4b7
[2023-08-28T20:47:14.296+0000] {taskinstance.py:1660} INFO - Exporting env vars: AIRFLOW_CTX_DAG_OWNER='***' AIRFLOW_CTX_DAG_ID='coin_data_dag' AIRFLOW_CTX_TASK_ID='fetch_insert_task_2017_01_13' AIRFLOW_CTX_EXECUTION_DATE='2023-08-28T20:47:09.619213+00:00' AIRFLOW_CTX_TRY_NUMBER='1' AIRFLOW_CTX_DAG_RUN_ID='manual__2023-08-28T20:47:09.619213+00:00'
[2023-08-28T20:47:14.628+0000] {taskinstance.py:1943} ERROR - Task failed with exception
Traceback (most recent call last):
  File "/home/airflow/.local/lib/python3.8/site-packages/airflow/operators/python.py", line 192, in execute
    return_value = self.execute_callable()
  File "/home/airflow/.local/lib/python3.8/site-packages/airflow/operators/python.py", line 209, in execute_callable
    return self.python_callable(*self.op_args, **self.op_kwargs)
  File "/opt/airflow/dags/coin_data_dag.py", line 29, in fetch_and_insert_data
    price_usd = data['market_data']['current_price']['usd']
KeyError: 'market_data'
[2023-08-28T20:47:14.649+0000] {taskinstance.py:1400} INFO - Marking task as UP_FOR_RETRY. dag_id=coin_data_dag, task_id=fetch_insert_task_2017_01_13, execution_date=20230828T204709, start_date=20230828T204714, end_date=20230828T204714
[2023-08-28T20:47:14.672+0000] {standard_task_runner.py:104} ERROR - Failed to execute job 50 for task fetch_insert_task_2017_01_13 ('market_data'; 2015)
[2023-08-28T20:47:14.709+0000] {local_task_job_runner.py:228} INFO - Task exited with return code 1
[2023-08-28T20:47:14.740+0000] {taskinstance.py:2784} INFO - 0 downstream tasks scheduled from follow-on schedule check
