[2023-08-28T20:52:16.472+0000] {taskinstance.py:1159} INFO - Dependencies all met for dep_context=non-requeueable deps ti=<TaskInstance: coin_data_dag.fetch_insert_task_2017_01_15 manual__2023-08-28T20:47:09.619213+00:00 [queued]>
[2023-08-28T20:52:16.482+0000] {taskinstance.py:1159} INFO - Dependencies all met for dep_context=requeueable deps ti=<TaskInstance: coin_data_dag.fetch_insert_task_2017_01_15 manual__2023-08-28T20:47:09.619213+00:00 [queued]>
[2023-08-28T20:52:16.483+0000] {taskinstance.py:1361} INFO - Starting attempt 2 of 2
[2023-08-28T20:52:16.496+0000] {taskinstance.py:1382} INFO - Executing <Task(PythonOperator): fetch_insert_task_2017_01_15> on 2023-08-28 20:47:09.619213+00:00
[2023-08-28T20:52:16.504+0000] {standard_task_runner.py:57} INFO - Started process 2103 to run task
[2023-08-28T20:52:16.509+0000] {standard_task_runner.py:84} INFO - Running: ['***', 'tasks', 'run', 'coin_data_dag', 'fetch_insert_task_2017_01_15', 'manual__2023-08-28T20:47:09.619213+00:00', '--job-id', '53', '--raw', '--subdir', 'DAGS_FOLDER/coin_data_dag.py', '--cfg-path', '/tmp/tmpdz9k60qm']
[2023-08-28T20:52:16.513+0000] {standard_task_runner.py:85} INFO - Job 53: Subtask fetch_insert_task_2017_01_15
[2023-08-28T20:52:16.570+0000] {task_command.py:415} INFO - Running <TaskInstance: coin_data_dag.fetch_insert_task_2017_01_15 manual__2023-08-28T20:47:09.619213+00:00 [running]> on host e5729120e4b7
[2023-08-28T20:52:16.649+0000] {taskinstance.py:1660} INFO - Exporting env vars: AIRFLOW_CTX_DAG_OWNER='***' AIRFLOW_CTX_DAG_ID='coin_data_dag' AIRFLOW_CTX_TASK_ID='fetch_insert_task_2017_01_15' AIRFLOW_CTX_EXECUTION_DATE='2023-08-28T20:47:09.619213+00:00' AIRFLOW_CTX_TRY_NUMBER='2' AIRFLOW_CTX_DAG_RUN_ID='manual__2023-08-28T20:47:09.619213+00:00'
[2023-08-28T20:52:16.940+0000] {taskinstance.py:1943} ERROR - Task failed with exception
Traceback (most recent call last):
  File "/home/airflow/.local/lib/python3.8/site-packages/airflow/operators/python.py", line 192, in execute
    return_value = self.execute_callable()
  File "/home/airflow/.local/lib/python3.8/site-packages/airflow/operators/python.py", line 209, in execute_callable
    return self.python_callable(*self.op_args, **self.op_kwargs)
  File "/opt/airflow/dags/coin_data_dag.py", line 29, in fetch_and_insert_data
    price_usd = data['market_data']['current_price']['usd']
KeyError: 'market_data'
[2023-08-28T20:52:16.952+0000] {taskinstance.py:1400} INFO - Marking task as FAILED. dag_id=coin_data_dag, task_id=fetch_insert_task_2017_01_15, execution_date=20230828T204709, start_date=20230828T205216, end_date=20230828T205216
[2023-08-28T20:52:16.965+0000] {standard_task_runner.py:104} ERROR - Failed to execute job 53 for task fetch_insert_task_2017_01_15 ('market_data'; 2103)
[2023-08-28T20:52:17.004+0000] {local_task_job_runner.py:228} INFO - Task exited with return code 1
[2023-08-28T20:52:17.027+0000] {taskinstance.py:2784} INFO - 0 downstream tasks scheduled from follow-on schedule check
