[2023-08-28T22:38:15.174+0000] {taskinstance.py:1159} INFO - Dependencies all met for dep_context=non-requeueable deps ti=<TaskInstance: crypto_data_download.create_table_task manual__2023-08-28T22:38:13.038580+00:00 [queued]>
[2023-08-28T22:38:15.183+0000] {taskinstance.py:1159} INFO - Dependencies all met for dep_context=requeueable deps ti=<TaskInstance: crypto_data_download.create_table_task manual__2023-08-28T22:38:13.038580+00:00 [queued]>
[2023-08-28T22:38:15.184+0000] {taskinstance.py:1361} INFO - Starting attempt 1 of 2
[2023-08-28T22:38:15.198+0000] {taskinstance.py:1382} INFO - Executing <Task(PythonOperator): create_table_task> on 2023-08-28 22:38:13.038580+00:00
[2023-08-28T22:38:15.205+0000] {standard_task_runner.py:57} INFO - Started process 302 to run task
[2023-08-28T22:38:15.210+0000] {standard_task_runner.py:84} INFO - Running: ['***', 'tasks', 'run', 'crypto_data_download', 'create_table_task', 'manual__2023-08-28T22:38:13.038580+00:00', '--job-id', '80', '--raw', '--subdir', 'DAGS_FOLDER/coin_data_dag.py', '--cfg-path', '/tmp/tmpa6i2a2zx']
[2023-08-28T22:38:15.215+0000] {standard_task_runner.py:85} INFO - Job 80: Subtask create_table_task
[2023-08-28T22:38:15.286+0000] {task_command.py:415} INFO - Running <TaskInstance: crypto_data_download.create_table_task manual__2023-08-28T22:38:13.038580+00:00 [running]> on host c7c637d36acf
[2023-08-28T22:38:15.387+0000] {taskinstance.py:1660} INFO - Exporting env vars: AIRFLOW_CTX_DAG_OWNER='your_name' AIRFLOW_CTX_DAG_ID='crypto_data_download' AIRFLOW_CTX_TASK_ID='create_table_task' AIRFLOW_CTX_EXECUTION_DATE='2023-08-28T22:38:13.038580+00:00' AIRFLOW_CTX_TRY_NUMBER='1' AIRFLOW_CTX_DAG_RUN_ID='manual__2023-08-28T22:38:13.038580+00:00'
[2023-08-28T22:38:15.411+0000] {taskinstance.py:1943} ERROR - Task failed with exception
Traceback (most recent call last):
  File "/home/airflow/.local/lib/python3.8/site-packages/airflow/operators/python.py", line 192, in execute
    return_value = self.execute_callable()
  File "/home/airflow/.local/lib/python3.8/site-packages/airflow/operators/python.py", line 209, in execute_callable
    return self.python_callable(*self.op_args, **self.op_kwargs)
  File "/opt/airflow/dags/coin_data_dag.py", line 28, in create_books_table_if_not_exists
    pg_hook.run(create_table_sql)
  File "/home/airflow/.local/lib/python3.8/site-packages/airflow/providers/common/sql/hooks/sql.py", line 385, in run
    with closing(self.get_conn()) as conn:
  File "/home/airflow/.local/lib/python3.8/site-packages/airflow/providers/postgres/hooks/postgres.py", line 124, in get_conn
    conn = deepcopy(self.connection or self.get_connection(conn_id))
  File "/home/airflow/.local/lib/python3.8/site-packages/airflow/hooks/base.py", line 72, in get_connection
    conn = Connection.get_connection_from_secrets(conn_id)
  File "/home/airflow/.local/lib/python3.8/site-packages/airflow/models/connection.py", line 477, in get_connection_from_secrets
    raise AirflowNotFoundException(f"The conn_id `{conn_id}` isn't defined")
airflow.exceptions.AirflowNotFoundException: The conn_id `postgres_connection` isn't defined
[2023-08-28T22:38:15.417+0000] {taskinstance.py:1400} INFO - Marking task as UP_FOR_RETRY. dag_id=crypto_data_download, task_id=create_table_task, execution_date=20230828T223813, start_date=20230828T223815, end_date=20230828T223815
[2023-08-28T22:38:15.431+0000] {standard_task_runner.py:104} ERROR - Failed to execute job 80 for task create_table_task (The conn_id `postgres_connection` isn't defined; 302)
[2023-08-28T22:38:15.464+0000] {local_task_job_runner.py:228} INFO - Task exited with return code 1
[2023-08-28T22:38:15.495+0000] {taskinstance.py:2784} INFO - 0 downstream tasks scheduled from follow-on schedule check
