[2023-08-30T22:46:31.459+0000] {taskinstance.py:1159} INFO - Dependencies all met for dep_context=non-requeueable deps ti=<TaskInstance: crypto_data_download.fetch_and_store_task scheduled__2023-08-29T21:09:49.059324+00:00 [queued]>
[2023-08-30T22:46:31.469+0000] {taskinstance.py:1159} INFO - Dependencies all met for dep_context=requeueable deps ti=<TaskInstance: crypto_data_download.fetch_and_store_task scheduled__2023-08-29T21:09:49.059324+00:00 [queued]>
[2023-08-30T22:46:31.470+0000] {taskinstance.py:1361} INFO - Starting attempt 1 of 2
[2023-08-30T22:46:31.489+0000] {taskinstance.py:1382} INFO - Executing <Task(PythonOperator): fetch_and_store_task> on 2023-08-29 21:09:49.059324+00:00
[2023-08-30T22:46:31.496+0000] {standard_task_runner.py:57} INFO - Started process 10262 to run task
[2023-08-30T22:46:31.501+0000] {standard_task_runner.py:84} INFO - Running: ['***', 'tasks', 'run', 'crypto_data_download', 'fetch_and_store_task', 'scheduled__2023-08-29T21:09:49.059324+00:00', '--job-id', '169', '--raw', '--subdir', 'DAGS_FOLDER/coin_data_dag.py', '--cfg-path', '/tmp/tmpvcfruman']
[2023-08-30T22:46:31.506+0000] {standard_task_runner.py:85} INFO - Job 169: Subtask fetch_and_store_task
[2023-08-30T22:46:31.569+0000] {task_command.py:415} INFO - Running <TaskInstance: crypto_data_download.fetch_and_store_task scheduled__2023-08-29T21:09:49.059324+00:00 [running]> on host 6c9aee5df47e
[2023-08-30T22:46:31.663+0000] {taskinstance.py:1660} INFO - Exporting env vars: AIRFLOW_CTX_DAG_OWNER='NicoB' AIRFLOW_CTX_DAG_ID='crypto_data_download' AIRFLOW_CTX_TASK_ID='fetch_and_store_task' AIRFLOW_CTX_EXECUTION_DATE='2023-08-29T21:09:49.059324+00:00' AIRFLOW_CTX_TRY_NUMBER='1' AIRFLOW_CTX_DAG_RUN_ID='scheduled__2023-08-29T21:09:49.059324+00:00'
[2023-08-30T22:46:31.688+0000] {taskinstance.py:1943} ERROR - Task failed with exception
Traceback (most recent call last):
  File "/home/airflow/.local/lib/python3.8/site-packages/urllib3/connection.py", line 174, in _new_conn
    conn = connection.create_connection(
  File "/home/airflow/.local/lib/python3.8/site-packages/urllib3/util/connection.py", line 72, in create_connection
    for res in socket.getaddrinfo(host, port, family, socket.SOCK_STREAM):
  File "/usr/local/lib/python3.8/socket.py", line 918, in getaddrinfo
    for res in _socket.getaddrinfo(host, port, family, type, proto, flags):
socket.gaierror: [Errno -2] Name or service not known

During handling of the above exception, another exception occurred:

Traceback (most recent call last):
  File "/home/airflow/.local/lib/python3.8/site-packages/urllib3/connectionpool.py", line 714, in urlopen
    httplib_response = self._make_request(
  File "/home/airflow/.local/lib/python3.8/site-packages/urllib3/connectionpool.py", line 403, in _make_request
    self._validate_conn(conn)
  File "/home/airflow/.local/lib/python3.8/site-packages/urllib3/connectionpool.py", line 1053, in _validate_conn
    conn.connect()
  File "/home/airflow/.local/lib/python3.8/site-packages/urllib3/connection.py", line 363, in connect
    self.sock = conn = self._new_conn()
  File "/home/airflow/.local/lib/python3.8/site-packages/urllib3/connection.py", line 186, in _new_conn
    raise NewConnectionError(
urllib3.exceptions.NewConnectionError: <urllib3.connection.HTTPSConnection object at 0x7f317032c040>: Failed to establish a new connection: [Errno -2] Name or service not known

During handling of the above exception, another exception occurred:

Traceback (most recent call last):
  File "/home/airflow/.local/lib/python3.8/site-packages/requests/adapters.py", line 486, in send
    resp = conn.urlopen(
  File "/home/airflow/.local/lib/python3.8/site-packages/urllib3/connectionpool.py", line 798, in urlopen
    retries = retries.increment(
  File "/home/airflow/.local/lib/python3.8/site-packages/urllib3/util/retry.py", line 592, in increment
    raise MaxRetryError(_pool, url, error or ResponseError(cause))
urllib3.exceptions.MaxRetryError: HTTPSConnectionPool(host='api.coingecko.com', port=443): Max retries exceeded with url: /api/v3/coins/bitcoin/history?date=13-01-2017 (Caused by NewConnectionError('<urllib3.connection.HTTPSConnection object at 0x7f317032c040>: Failed to establish a new connection: [Errno -2] Name or service not known'))

During handling of the above exception, another exception occurred:

Traceback (most recent call last):
  File "/home/airflow/.local/lib/python3.8/site-packages/airflow/operators/python.py", line 192, in execute
    return_value = self.execute_callable()
  File "/home/airflow/.local/lib/python3.8/site-packages/airflow/operators/python.py", line 209, in execute_callable
    return self.python_callable(*self.op_args, **self.op_kwargs)
  File "/opt/airflow/dags/coin_data_dag.py", line 65, in fetch_and_store_data_for_range
    fetch_and_store_data_for_date(formatted_date, coin_id)
  File "/opt/airflow/dags/coin_data_dag.py", line 40, in fetch_and_store_data_for_date
    response = requests.get(url)
  File "/home/airflow/.local/lib/python3.8/site-packages/requests/api.py", line 73, in get
    return request("get", url, params=params, **kwargs)
  File "/home/airflow/.local/lib/python3.8/site-packages/requests/api.py", line 59, in request
    return session.request(method=method, url=url, **kwargs)
  File "/home/airflow/.local/lib/python3.8/site-packages/requests/sessions.py", line 589, in request
    resp = self.send(prep, **send_kwargs)
  File "/home/airflow/.local/lib/python3.8/site-packages/requests/sessions.py", line 703, in send
    r = adapter.send(request, **kwargs)
  File "/home/airflow/.local/lib/python3.8/site-packages/requests/adapters.py", line 519, in send
    raise ConnectionError(e, request=request)
requests.exceptions.ConnectionError: HTTPSConnectionPool(host='api.coingecko.com', port=443): Max retries exceeded with url: /api/v3/coins/bitcoin/history?date=13-01-2017 (Caused by NewConnectionError('<urllib3.connection.HTTPSConnection object at 0x7f317032c040>: Failed to establish a new connection: [Errno -2] Name or service not known'))
[2023-08-30T22:46:31.704+0000] {taskinstance.py:1400} INFO - Marking task as UP_FOR_RETRY. dag_id=crypto_data_download, task_id=fetch_and_store_task, execution_date=20230829T210949, start_date=20230830T224631, end_date=20230830T224631
[2023-08-30T22:46:31.716+0000] {standard_task_runner.py:104} ERROR - Failed to execute job 169 for task fetch_and_store_task (HTTPSConnectionPool(host='api.coingecko.com', port=443): Max retries exceeded with url: /api/v3/coins/bitcoin/history?date=13-01-2017 (Caused by NewConnectionError('<urllib3.connection.HTTPSConnection object at 0x7f317032c040>: Failed to establish a new connection: [Errno -2] Name or service not known')); 10262)
[2023-08-30T22:46:31.754+0000] {local_task_job_runner.py:228} INFO - Task exited with return code 1
[2023-08-30T22:46:31.773+0000] {taskinstance.py:2784} INFO - 0 downstream tasks scheduled from follow-on schedule check
