[2023-08-28T22:06:37.725+0000] {taskinstance.py:1159} INFO - Dependencies all met for dep_context=non-requeueable deps ti=<TaskInstance: crypto_data_download.download_crypto_data_task manual__2023-08-28T22:06:36.170816+00:00 [queued]>
[2023-08-28T22:06:37.734+0000] {taskinstance.py:1159} INFO - Dependencies all met for dep_context=requeueable deps ti=<TaskInstance: crypto_data_download.download_crypto_data_task manual__2023-08-28T22:06:36.170816+00:00 [queued]>
[2023-08-28T22:06:37.735+0000] {taskinstance.py:1361} INFO - Starting attempt 1 of 2
[2023-08-28T22:06:37.749+0000] {taskinstance.py:1382} INFO - Executing <Task(PythonOperator): download_crypto_data_task> on 2023-08-28 22:06:36.170816+00:00
[2023-08-28T22:06:37.756+0000] {standard_task_runner.py:57} INFO - Started process 3258 to run task
[2023-08-28T22:06:37.761+0000] {standard_task_runner.py:84} INFO - Running: ['***', 'tasks', 'run', 'crypto_data_download', 'download_crypto_data_task', 'manual__2023-08-28T22:06:36.170816+00:00', '--job-id', '65', '--raw', '--subdir', 'DAGS_FOLDER/coin_data_dag.py', '--cfg-path', '/tmp/tmpdj84f_ye']
[2023-08-28T22:06:37.765+0000] {standard_task_runner.py:85} INFO - Job 65: Subtask download_crypto_data_task
[2023-08-28T22:06:37.823+0000] {task_command.py:415} INFO - Running <TaskInstance: crypto_data_download.download_crypto_data_task manual__2023-08-28T22:06:36.170816+00:00 [running]> on host e5729120e4b7
[2023-08-28T22:06:37.918+0000] {taskinstance.py:1660} INFO - Exporting env vars: AIRFLOW_CTX_DAG_OWNER='your_name' AIRFLOW_CTX_DAG_ID='crypto_data_download' AIRFLOW_CTX_TASK_ID='download_crypto_data_task' AIRFLOW_CTX_EXECUTION_DATE='2023-08-28T22:06:36.170816+00:00' AIRFLOW_CTX_TRY_NUMBER='1' AIRFLOW_CTX_DAG_RUN_ID='manual__2023-08-28T22:06:36.170816+00:00'
[2023-08-28T22:06:38.066+0000] {logging_mixin.py:151} INFO - https://api.coingecko.com/api/v3/coins/bitcoin/history?date=01-08-2023
[2023-08-28T22:06:38.068+0000] {logging_mixin.py:151} INFO - Data for 01-08-2023 downloaded and saved to crypto_data_01-08-2023.json!
[2023-08-28T22:06:38.080+0000] {base.py:73} INFO - Using connection ID 'postgres_localhost' for task execution.
[2023-08-28T22:06:38.082+0000] {taskinstance.py:1943} ERROR - Task failed with exception
Traceback (most recent call last):
  File "/home/airflow/.local/lib/python3.8/site-packages/airflow/operators/python.py", line 192, in execute
    return_value = self.execute_callable()
  File "/home/airflow/.local/lib/python3.8/site-packages/airflow/operators/python.py", line 209, in execute_callable
    return self.python_callable(*self.op_args, **self.op_kwargs)
  File "/opt/airflow/dags/coin_data_dag.py", line 50, in download_crypto_data_for_range
    download_crypto_data_for_date(current_date.strftime('%d-%m-%Y'))
  File "/opt/airflow/dags/coin_data_dag.py", line 44, in download_crypto_data_for_date
    pg_hook.run(insert_query, parameters=(coin_id, price_usd, date, json.dumps(data)))
  File "/home/airflow/.local/lib/python3.8/site-packages/airflow/providers/common/sql/hooks/sql.py", line 385, in run
    with closing(self.get_conn()) as conn:
  File "/home/airflow/.local/lib/python3.8/site-packages/airflow/providers/postgres/hooks/postgres.py", line 154, in get_conn
    self.conn = psycopg2.connect(**conn_args)
  File "/home/airflow/.local/lib/python3.8/site-packages/psycopg2/__init__.py", line 122, in connect
    conn = _connect(dsn, connection_factory=connection_factory, **kwasync)
psycopg2.OperationalError: connection to server at "localhost" (127.0.0.1), port 5432 failed: Connection refused
	Is the server running on that host and accepting TCP/IP connections?
connection to server at "localhost" (::1), port 5432 failed: Cannot assign requested address
	Is the server running on that host and accepting TCP/IP connections?

[2023-08-28T22:06:38.093+0000] {taskinstance.py:1400} INFO - Marking task as UP_FOR_RETRY. dag_id=crypto_data_download, task_id=download_crypto_data_task, execution_date=20230828T220636, start_date=20230828T220637, end_date=20230828T220638
[2023-08-28T22:06:38.107+0000] {standard_task_runner.py:104} ERROR - Failed to execute job 65 for task download_crypto_data_task (connection to server at "localhost" (127.0.0.1), port 5432 failed: Connection refused
	Is the server running on that host and accepting TCP/IP connections?
connection to server at "localhost" (::1), port 5432 failed: Cannot assign requested address
	Is the server running on that host and accepting TCP/IP connections?
; 3258)
[2023-08-28T22:06:38.135+0000] {local_task_job_runner.py:228} INFO - Task exited with return code 1
[2023-08-28T22:06:38.156+0000] {taskinstance.py:2784} INFO - 0 downstream tasks scheduled from follow-on schedule check
