[2023-08-28T22:50:58.154+0000] {taskinstance.py:1159} INFO - Dependencies all met for dep_context=non-requeueable deps ti=<TaskInstance: crypto_data_download.create_table_task manual__2023-08-28T22:45:53.380908+00:00 [queued]>
[2023-08-28T22:50:58.165+0000] {taskinstance.py:1159} INFO - Dependencies all met for dep_context=requeueable deps ti=<TaskInstance: crypto_data_download.create_table_task manual__2023-08-28T22:45:53.380908+00:00 [queued]>
[2023-08-28T22:50:58.166+0000] {taskinstance.py:1361} INFO - Starting attempt 2 of 2
[2023-08-28T22:50:58.183+0000] {taskinstance.py:1382} INFO - Executing <Task(PythonOperator): create_table_task> on 2023-08-28 22:45:53.380908+00:00
[2023-08-28T22:50:58.189+0000] {standard_task_runner.py:57} INFO - Started process 145 to run task
[2023-08-28T22:50:58.195+0000] {standard_task_runner.py:84} INFO - Running: ['***', 'tasks', 'run', 'crypto_data_download', 'create_table_task', 'manual__2023-08-28T22:45:53.380908+00:00', '--job-id', '87', '--raw', '--subdir', 'DAGS_FOLDER/coin_data_dag.py', '--cfg-path', '/tmp/tmpisl0m0ne']
[2023-08-28T22:50:58.199+0000] {standard_task_runner.py:85} INFO - Job 87: Subtask create_table_task
[2023-08-28T22:50:58.263+0000] {task_command.py:415} INFO - Running <TaskInstance: crypto_data_download.create_table_task manual__2023-08-28T22:45:53.380908+00:00 [running]> on host 21f1aaa5a4ba
[2023-08-28T22:50:58.361+0000] {taskinstance.py:1660} INFO - Exporting env vars: AIRFLOW_CTX_DAG_OWNER='your_name' AIRFLOW_CTX_DAG_ID='crypto_data_download' AIRFLOW_CTX_TASK_ID='create_table_task' AIRFLOW_CTX_EXECUTION_DATE='2023-08-28T22:45:53.380908+00:00' AIRFLOW_CTX_TRY_NUMBER='2' AIRFLOW_CTX_DAG_RUN_ID='manual__2023-08-28T22:45:53.380908+00:00'
[2023-08-28T22:50:58.375+0000] {base.py:73} INFO - Using connection ID 'postgres_localhost' for task execution.
[2023-08-28T22:50:58.377+0000] {taskinstance.py:1943} ERROR - Task failed with exception
Traceback (most recent call last):
  File "/home/airflow/.local/lib/python3.8/site-packages/airflow/operators/python.py", line 192, in execute
    return_value = self.execute_callable()
  File "/home/airflow/.local/lib/python3.8/site-packages/airflow/operators/python.py", line 209, in execute_callable
    return self.python_callable(*self.op_args, **self.op_kwargs)
  File "/opt/airflow/dags/coin_data_dag.py", line 28, in create_books_table_if_not_exists
    pg_hook.run(create_table_sql)
  File "/home/airflow/.local/lib/python3.8/site-packages/airflow/providers/common/sql/hooks/sql.py", line 385, in run
    with closing(self.get_conn()) as conn:
  File "/home/airflow/.local/lib/python3.8/site-packages/airflow/providers/postgres/hooks/postgres.py", line 154, in get_conn
    self.conn = psycopg2.connect(**conn_args)
  File "/home/airflow/.local/lib/python3.8/site-packages/psycopg2/__init__.py", line 122, in connect
    conn = _connect(dsn, connection_factory=connection_factory, **kwasync)
psycopg2.OperationalError: connection to server at "127.0.0.1", port 5432 failed: Connection refused
	Is the server running on that host and accepting TCP/IP connections?

[2023-08-28T22:50:58.389+0000] {taskinstance.py:1400} INFO - Marking task as FAILED. dag_id=crypto_data_download, task_id=create_table_task, execution_date=20230828T224553, start_date=20230828T225058, end_date=20230828T225058
[2023-08-28T22:50:58.402+0000] {standard_task_runner.py:104} ERROR - Failed to execute job 87 for task create_table_task (connection to server at "127.0.0.1", port 5432 failed: Connection refused
	Is the server running on that host and accepting TCP/IP connections?
; 145)
[2023-08-28T22:50:58.447+0000] {local_task_job_runner.py:228} INFO - Task exited with return code 1
[2023-08-28T22:50:58.470+0000] {taskinstance.py:2784} INFO - 0 downstream tasks scheduled from follow-on schedule check
